Workbook

Sheet Assumptions
A1: RampCo Driver-Based FP&A Model — Pricing, Forecast, CVP
D2: Annual units | E2: 1240 | H2: Scenario List
A3: Scenario | B3: Base Case | D3: Shipping Cost / Unit (Input from Member 3 logistics) | E3: 91 | H3: Base Case
A4: If you do not see the arrow: click the cell (B3), then press Alt + Down Arrow. | D4: Annual Fixed Costs (placeholder) | E4: =SUM(F28,F33,B47) -> 225192.54 | H4: Downside Case
H5: Upside Case
D6: Pricing Method | E6: Cost-Plus
D7: Cost-Plus Markup % | E7: 0.4 | H7: Pricing Method List
D8: Target CM % | E8: 0.3 | H8: Cost-Plus
H9: Target CM%
A10: Product | B10: Product Mix % | C10: Annual Units (Base) | D10: BOM Materials / Unit | E10: Labor $ / Unit | F10: Other Var $ / Unit | G10: Shipping $ / Unit | H10: Total Var Cost / Unit | I10: Price / Unit | J10: CM / Unit | K10: CM % | M10: Adj Units | N10: Adj Mat | O10: Adj Labor | P10: Adj Other | Q10: Adj Ship | R10: Adj VarCost | S10: Adj Price
A11: Quarter Pipe | B11: 0.2 | C11: =B11*$E$2 -> 248 | D11: =F52 -> 336.52 | E11: =AVERAGE($D$29:$D$31)*B147 -> 50.666667 | F11: 0 | G11: =$E$3 -> 91 | H11: =D11+E11+F11+G11 -> 478.18667 | I11: =IF($E$6="Cost-Plus",H11*(1+$E$7),H11/(1-$E$8)) -> 669.46133 | J11: =I11-H11 -> 191.27467 | K11: =IF(I11=0,0,J11/I11) -> 0.28571429 | M11: =C11*$F$20 -> 248 | N11: =D11*$F$21 -> 336.52 | O11: =E11*$F$22 -> 50.666667 | P11: =F11*$F$24 -> 0 | Q11: =$E$3*$F$23 -> 91 | R11: =N11+O11+P11+Q11 -> 478.18667 | S11: =IF($E$6="Cost-Plus",R11*(1+$E$7),R11/(1-$E$8)) -> 669.46133
A12: Bank Ramp | B12: 0.2 | C12: =B12*$E$2 -> 248 | D12: =F69 -> 246.22 | E12: =AVERAGE($D$29:$D$31)*B148 -> 76 | F12: 0 | G12: =$E$3 -> 91 | H12: =D12+E12+F12+G12 -> 413.22 | I12: =IF($E$6="Cost-Plus",H12*(1+$E$7),H12/(1-$E$8)) -> 578.508 | J12: =I12-H12 -> 165.288 | K12: =IF(I12=0,0,J12/I12) -> 0.28571429 | M12: =C12*$F$20 -> 248 | N12: =D12*$F$21 -> 246.22 | O12: =E12*$F$22 -> 76 | P12: =F12*$F$24 -> 0 | Q12: =$E$3*$F$23 -> 91 | R12: =N12+O12+P12+Q12 -> 413.22 | S12: =IF($E$6="Cost-Plus",R12*(1+$E$7),R12/(1-$E$8)) -> 578.508
A13: Funbox | B13: 0.25 | C13: =B13*$E$2 -> 310 | D13: =F86 -> 1725.14 | E13: =AVERAGE($D$29:$D$31)*B149 -> 152 | F13: 0 | G13: =$E$3 -> 91 | H13: =D13+E13+F13+G13 -> 1968.14 | I13: =IF($E$6="Cost-Plus",H13*(1+$E$7),H13/(1-$E$8)) -> 2755.396 | J13: =I13-H13 -> 787.256 | K13: =IF(I13=0,0,J13/I13) -> 0.28571429 | M13: =C13*$F$20 -> 310 | N13: =D13*$F$21 -> 1725.14 | O13: =E13*$F$22 -> 152 | P13: =F13*$F$24 -> 0 | Q13: =$E$3*$F$23 -> 91 | R13: =N13+O13+P13+Q13 -> 1968.14 | S13: =IF($E$6="Cost-Plus",R13*(1+$E$7),R13/(1-$E$8)) -> 2755.396
A14: Launch Ramp | B14: 0.1 | C14: =B14*$E$2 -> 124 | D14: =F102 -> 162.73 | E14: =AVERAGE($D$29:$D$31)*B150 -> 101.33333 | F14: 0 | G14: =$E$3 -> 91 | H14: =D14+E14+F14+G14 -> 355.06333 | I14: =IF($E$6="Cost-Plus",H14*(1+$E$7),H14/(1-$E$8)) -> 497.08867 | J14: =I14-H14 -> 142.02533 | K14: =IF(I14=0,0,J14/I14) -> 0.28571429 | M14: =C14*$F$20 -> 124 | N14: =D14*$F$21 -> 162.73 | O14: =E14*$F$22 -> 101.33333 | P14: =F14*$F$24 -> 0 | Q14: =$E$3*$F$23 -> 91 | R14: =N14+O14+P14+Q14 -> 355.06333 | S14: =IF($E$6="Cost-Plus",R14*(1+$E$7),R14/(1-$E$8)) -> 497.08867
A15: Skatelite Upgrade | B15: 0.15 | C15: =B15*$E$2 -> 186 | D15: =SUM(F63,F79,F96,F112) -> 3772.13 | E15: =AVERAGE($D$29:$D$31)*B151 -> 12.666667 | F15: 0 | G15: =$E$3 -> 91 | H15: =D15+E15+F15+G15 -> 3875.7967 | I15: =IF($E$6="Cost-Plus",H15*(1+$E$7),H15/(1-$E$8)) -> 5426.1153 | J15: =I15-H15 -> 1550.3187 | K15: =IF(I15=0,0,J15/I15) -> 0.28571429 | M15: =C15*$F$20 -> 186 | N15: =D15*$F$21 -> 3772.13 | O15: =E15*$F$22 -> 12.666667 | P15: =F15*$F$24 -> 0 | Q15: =$E$3*$F$23 -> 91 | R15: =N15+O15+P15+Q15 -> 3875.7967 | S15: =IF($E$6="Cost-Plus",R15*(1+$E$7),R15/(1-$E$8)) -> 5426.1153
A16: Coping Upgrade | B16: 0.1 | C16: =B16*$E$2 -> 124 | D16: =SUM(F64,F80,F97,F113) -> 262.43 | E16: =AVERAGE($D$29:$D$31)*B152 -> 12.666667 | F16: 0 | G16: =$E$3 -> 91 | H16: =D16+E16+F16+G16 -> 366.09667 | I16: =IF($E$6="Cost-Plus",H16*(1+$E$7),H16/(1-$E$8)) -> 512.53533 | J16: =I16-H16 -> 146.43867 | K16: =IF(I16=0,0,J16/I16) -> 0.28571429 | M16: =C16*$F$20 -> 124 | N16: =D16*$F$21 -> 262.43 | O16: =E16*$F$22 -> 12.666667 | P16: =F16*$F$24 -> 0 | Q16: =$E$3*$F$23 -> 91 | R16: =N16+O16+P16+Q16 -> 366.09667 | S16: =IF($E$6="Cost-Plus",R16*(1+$E$7),R16/(1-$E$8)) -> 512.53533
A18: Scenario Multipliers
A19: Driver | B19: Base Case | C19: Downside Case | D19: Upside Case | E19: Selected Multipliers
A20: Units | B20: 1 | C20: 0.8 | D20: 1.15 | E20: Units Mult | F20: {=INDEX($B$20:$D$20, MATCH($B$3,$B$19:$D$19,0))} -> 1
A21: Materials | B21: 1 | C21: 1.1 | D21: 0.95 | E21: Materials Mult | F21: {=INDEX($B$21:$D$21, MATCH($B$3,$B$19:$D$19,0))} -> 1
A22: Labor | B22: 1 | C22: 1.1 | D22: 0.95 | E22: Labor Mult | F22: {=INDEX($B$22:$D$22, MATCH($B$3,$B$19:$D$19,0))} -> 1
A23: Shipping | B23: 1 | C23: 1.15 | D23: 0.95 | E23: Shipping Mult | F23: {=INDEX($B$23:$D$23, MATCH($B$3,$B$19:$D$19,0))} -> 1
A24: Other Var | B24: 1 | C24: 1.05 | D24: 0.98 | E24: Other Var Mult | F24: {=INDEX($B$24:$D$24, MATCH($B$3,$B$19:$D$19,0))} -> 1
A26: Labor Rates
A27: Role | B27: Direct or Indirect | C27: Fixed or Variable | D27: Hourly Rate $ | E27: Annual Hours | F27: Annual Cost $ | G27: Reference (hourly rate)
A28: General Manager | B28: Indirect | C28: Fixed | D28: 48 | E28: 2080 | F28: =D28*E28 -> 99840 | G28: https://www.glassdoor.com/Salaries/san-diego-general-and-operations-manager-salary-SRCH_IL.0,9_IC1147311_KO10,40.htm
A29: Production Lead | B29: Direct | C29: Variable | D29: 28 | E29: 2080 | F29: =D29*E29 -> 58240 | G29: https://www.indeed.com/career/production-lead/salaries/San-Diego--CA
A30: Production Specialist 1 | B30: Direct | C30: Variable | D30: 24 | E30: 2080 | F30: =D30*E30 -> 49920 | G30: https://www.indeed.com/career/production-specialist/salaries/San-Diego--CA?from=top_sb
A31: Production Specialist 2 | B31: Direct | C31: Variable | D31: 24 | E31: 2080 | F31: =D31*E31 -> 49920 | G31: https://www.indeed.com/career/production-specialist/salaries/San-Diego--CA?from=top_sb
A32: Procurement & Inventory Coordinator | B32: Indirect | C32: Variable | D32: 25 | E32: 2080 | F32: =D32*E32 -> 52000 | G32: https://www.indeed.com/career/inventory-manager/salaries/San-Diego--CA
A33: Accounting & Admin Manager | B33: Indirect | C33: Fixed | D33: 35 | E33: 2080 | F33: =D33*E33 -> 72800 | G33: https://www.indeed.com/career/account-manager/salaries/San-Diego--CA
A35: Facility Overhead
A36: Item | B36: Value | C36: Unit | D36: Reference
A37: Warehouse sqft | B37: 2000 | C37: sq ft
A38: Rent rate per sqft per month | B38: 1.5 | C38: $ | D38: https://www.propertyshark.com/cre/industrial/us/ca/san-diego/
A39: Monthly Rent Calculated | B39: =B38*B37 -> 3000 | C39: $
A40: Annual Rent Calculated | B40: =B39*12 -> 36000 | C40: $
A41: Electricity per year | B41: =750*12 -> 9000 | C41: $ | D41: https://www.electricitylocal.com/states/california/san-diego/
A42: Water per year | B42: =100*12 -> 1200 | C42: $ | D42: https://www.sandiego.gov/public-utilities/customer-support/water-billing-rates
A43: Insurance per year | B43: =400*12 -> 4800 | C43: $ | D43: https://isu-armac.com/california-business-insurance-rates/
...

Sheet ABC Allocation
A2: Overhead Rates ABC
A3: Metric | B3: Value | C3: Notes
A4: Facility Overhead Annual | B4: =Assumptions!B47 -> 52552.543 | C4: $ (link from Facilities Overhead)
A5: Total Production Labor Hours Annual | B5: =SUM(Assumptions!E29:E31) -> 6240 | C5: hours
A6: Facility Overhead Rate per Labor Hour | B6: =B4/B5 -> 8.4218819 | C6: $/labor hour
A7: Indirect Annual Labor cost | B7: =SUM(Assumptions!F32:F33,Assumptions!F28) -> 224640 | C7: $ (from indirect labor salaries)
A8: Total Batches Shipped Annual | B8: =SUM(F14:F19) -> 1395 | C8: batches (From CVP sheet)
A9: Indirect Labor Rate per Batch | B9: =B7/B8 -> 161.03226 | C9: $/batch
A12: ABC allocation
A13: Product | B13: Annual Units | C13: Labor Hours per Unit | D13: Batches per Unit | E13: Total Labor Hours | F13: Total Batches | G13: Facility O.H Allocated | H13: Indirect O.H Allocated | I13: Total Overhead Allocated | J13: Total O.H per Unit
A14: Quarter Pipe | B14: =Assumptions!C11 -> 248 | C14: =Assumptions!B147 -> 2 | D14: =Assumptions!C52 -> 1 | E14: =B14*C14 -> 496 | F14: =B14*D14 -> 248 | G14: =E14*$B$6 -> 4177.2534 | H14: =F14*$B$9 -> 39936 | I14: =G14+H14 -> 44113.253 | J14: =IF(B14=0,0,I14/B14) -> 177.87602
A15: Bank Ramp | B15: =Assumptions!C12 -> 248 | C15: =Assumptions!B148 -> 3 | D15: =Assumptions!C69 -> 1 | E15: =B15*C15 -> 744 | F15: =B15*D15 -> 248 | G15: =E15*$B$6 -> 6265.8801 | H15: =F15*$B$9 -> 39936 | I15: =G15+H15 -> 46201.88 | J15: =IF(B15=0,0,I15/B15) -> 186.2979
A16: Funbox | B16: =Assumptions!C13 -> 310 | C16: =Assumptions!B149 -> 6 | D16: 2 | E16: =B16*C16 -> 1860 | F16: =B16*D16 -> 620 | G16: =E16*$B$6 -> 15664.7 | H16: =F16*$B$9 -> 99840 | I16: =G16+H16 -> 115504.7 | J16: =IF(B16=0,0,I16/B16) -> 372.59581
A17: Launch Ramp | B17: =Assumptions!C14 -> 124 | C17: =Assumptions!B150 -> 4 | D17: =Assumptions!C102 -> 1 | E17: =B17*C17 -> 496 | F17: =B17*D17 -> 124 | G17: =E17*$B$6 -> 4177.2534 | H17: =F17*$B$9 -> 19968 | I17: =G17+H17 -> 24145.253 | J17: =IF(B17=0,0,I17/B17) -> 194.71979
A18: Accessory 1 | B18: =Assumptions!C15 -> 186 | C18: =Assumptions!B151 -> 0.5 | D18: 0.5 | E18: =B18*C18 -> 93 | F18: =B18*D18 -> 93 | G18: =E18*$B$6 -> 783.23501 | H18: =F18*$B$9 -> 14976 | I18: =G18+H18 -> 15759.235 | J18: =IF(B18=0,0,I18/B18) -> 84.72707
A19: Accessory 2 | B19: =Assumptions!C16 -> 124 | C19: =Assumptions!B152 -> 0.5 | D19: 0.5 | E19: =B19*C19 -> 62 | F19: =B19*D19 -> 62 | G19: =E19*$B$6 -> 522.15668 | H19: =F19*$B$9 -> 9984 | I19: =G19+H19 -> 10506.157 | J19: =IF(B19=0,0,I19/B19) -> 84.72707

Sheet Monthly FP&A
A1: Monthly FP&A Forecast (Units, Revenue, Variable Cost, Contribution Margin)
E2: Jan | I2: Feb | M2: Mar | Q2: Apr | U2: May | Y2: Jun | AC2: Jul | AG2: Aug | AK2: Sep | AO2: Oct | AS2: Nov | AW2: Dec
A3: Product | B3: Adj Annual Units | C3: Adj Price | D3: Adj Var Cost / Unit | E3: Units | F3: Revenue | G3: Var Cost | H3: CM | I3: Units | J3: Revenue | K3: Var Cost | L3: CM | M3: Units | N3: Revenue | O3: Var Cost | P3: CM | Q3: Units | R3: Revenue | S3: Var Cost | T3: CM | U3: Units | V3: Revenue | W3: Var Cost | X3: CM | Y3: Units | Z3: Revenue | AA3: Var Cost | AB3: CM | AC3: Units | AD3: Revenue | AE3: Var Cost | AF3: CM | AG3: Units | AH3: Revenue | AI3: Var Cost | AJ3: CM | AK3: Units | AL3: Revenue | AM3: Var Cost | AN3: CM | AO3: Units | AP3: Revenue | AQ3: Var Cost | AR3: CM | AS3: Units | AT3: Revenue | AU3: Var Cost | AV3: CM | AW3: Units | AX3: Revenue | AY3: Var Cost | AZ3: CM
A4: Quarter Pipe | B4: =Assumptions!M11 -> 248 | C4: =Assumptions!S11 -> 669.46133 | D4: =Assumptions!R11 -> 478.18667 | E4: =$B4/12 -> 20.666667 | F4: =E4*$C4 -> 13835.534 | G4: =E4*$D4 -> 9882.5244 | H4: =F4-G4 -> 3953.0098 | I4: =$B4/12 -> 20.666667 | J4: =I4*$C4 -> 13835.534 | K4: =I4*$D4 -> 9882.5244 | L4: =J4-K4 -> 3953.0098 | M4: =$B4/12 -> 20.666667 | N4: =M4*$C4 -> 13835.534 | O4: =M4*$D4 -> 9882.5244 | P4: =N4-O4 -> 3953.0098 | Q4: =$B4/12 -> 20.666667 | R4: =Q4*$C4 -> 13835.534 | S4: =Q4*$D4 -> 9882.5244 | T4: =R4-S4 -> 3953.0098 | U4: =$B4/12 -> 20.666667 | V4: =U4*$C4 -> 13835.534 | W4: =U4*$D4 -> 9882.5244 | X4: =V4-W4 -> 3953.0098 | Y4: =$B4/12 -> 20.666667 | Z4: =Y4*$C4 -> 13835.534 | AA4: =Y4*$D4 -> 9882.5244 | AB4: =Z4-AA4 -> 3953.0098 | AC4: =$B4/12 -> 20.666667 | AD4: =AC4*$C4 -> 13835.534 | AE4: =AC4*$D4 -> 9882.5244 | AF4: =AD4-AE4 -> 3953.0098 | AG4: =$B4/12 -> 20.666667 | AH4: =AG4*$C4 -> 13835.534 | AI4: =AG4*$D4 -> 9882.5244 | AJ4: =AH4-AI4 -> 3953.0098 | AK4: =$B4/12 -> 20.666667 | AL4: =AK4*$C4 -> 13835.534 | AM4: =AK4*$D4 -> 9882.5244 | AN4: =AL4-AM4 -> 3953.0098 | AO4: =$B4/12 -> 20.666667 | AP4: =AO4*$C4 -> 13835.534 | AQ4: =AO4*$D4 -> 9882.5244 | AR4: =AP4-AQ4 -> 3953.0098 | AS4: =$B4/12 -> 20.666667 | AT4: =AS4*$C4 -> 13835.534 | AU4: =AS4*$D4 -> 9882.5244 | AV4: =AT4-AU4 -> 3953.0098 | AW4: =$B4/12 -> 20.666667 | AX4: =AW4*$C4 -> 13835.534 | AY4: =AW4*$D4 -> 9882.5244 | AZ4: =AX4-AY4 -> 3953.0098
A5: Bank Ramp | B5: =Assumptions!M12 -> 248 | C5: =Assumptions!S12 -> 578.508 | D5: =Assumptions!R12 -> 413.22 | E5: =$B5/12 -> 20.666667 | F5: =E5*$C5 -> 11955.832 | G5: =E5*$D5 -> 8539.88 | H5: =F5-G5 -> 3415.952 | I5: =$B5/12 -> 20.666667 | J5: =I5*$C5 -> 11955.832 | K5: =I5*$D5 -> 8539.88 | L5: =J5-K5 -> 3415.952 | M5: =$B5/12 -> 20.666667 | N5: =M5*$C5 -> 11955.832 | O5: =M5*$D5 -> 8539.88 | P5: =N5-O5 -> 3415.952 | Q5: =$B5/12 -> 20.666667 | R5: =Q5*$C5 -> 11955.832 | S5: =Q5*$D5 -> 8539.88 | T5: =R5-S5 -> 3415.952 | U5: =$B5/12 -> 20.666667 | V5: =U5*$C5 -> 11955.832 | W5: =U5*$D5 -> 8539.88 | X5: =V5-W5 -> 3415.952 | Y5: =$B5/12 -> 20.666667 | Z5: =Y5*$C5 -> 11955.832 | AA5: =Y5*$D5 -> 8539.88 | AB5: =Z5-AA5 -> 3415.952 | AC5: =$B5/12 -> 20.666667 | AD5: =AC5*$C5 -> 11955.832 | AE5: =AC5*$D5 -> 8539.88 | AF5: =AD5-AE5 -> 3415.952 | AG5: =$B5/12 -> 20.666667 | AH5: =AG5*$C5 -> 11955.832 | AI5: =AG5*$D5 -> 8539.88 | AJ5: =AH5-AI5 -> 3415.952 | AK5: =$B5/12 -> 20.666667 | AL5: =AK5*$C5 -> 11955.832 | AM5: =AK5*$D5 -> 8539.88 | AN5: =AL5-AM5 -> 3415.952 | AO5: =$B5/12 -> 20.666667 | AP5: =AO5*$C5 -> 11955.832 | AQ5: =AO5*$D5 -> 8539.88 | AR5: =AP5-AQ5 -> 3415.952 | AS5: =$B5/12 -> 20.666667 | AT5: =AS5*$C5 -> 11955.832 | AU5: =AS5*$D5 -> 8539.88 | AV5: =AT5-AU5 -> 3415.952 | AW5: =$B5/12 -> 20.666667 | AX5: =AW5*$C5 -> 11955.832 | AY5: =AW5*$D5 -> 8539.88 | AZ5: =AX5-AY5 -> 3415.952
A6: Funbox | B6: =Assumptions!M13 -> 310 | C6: =Assumptions!S13 -> 2755.396 | D6: =Assumptions!R13 -> 1968.14 | E6: =$B6/12 -> 25.833333 | F6: =E6*$C6 -> 71181.063 | G6: =E6*$D6 -> 50843.617 | H6: =F6-G6 -> 20337.447 | I6: =$B6/12 -> 25.833333 | J6: =I6*$C6 -> 71181.063 | K6: =I6*$D6 -> 50843.617 | L6: =J6-K6 -> 20337.447 | M6: =$B6/12 -> 25.833333 | N6: =M6*$C6 -> 71181.063 | O6: =M6*$D6 -> 50843.617 | P6: =N6-O6 -> 20337.447 | Q6: =$B6/12 -> 25.833333 | R6: =Q6*$C6 -> 71181.063 | S6: =Q6*$D6 -> 50843.617 | T6: =R6-S6 -> 20337.447 | U6: =$B6/12 -> 25.833333 | V6: =U6*$C6 -> 71181.063 | W6: =U6*$D6 -> 50843.617 | X6: =V6-W6 -> 20337.447 | Y6: =$B6/12 -> 25.833333 | Z6: =Y6*$C6 -> 71181.063 | AA6: =Y6*$D6 -> 50843.617 | AB6: =Z6-AA6 -> 20337.447 | AC6: =$B6/12 -> 25.833333 | AD6: =AC6*$C6 -> 71181.063 | AE6: =AC6*$D6 -> 50843.617 | AF6: =AD6-AE6 -> 20337.447 | AG6: =$B6/12 -> 25.833333 | AH6: =AG6*$C6 -> 71181.063 | AI6: =AG6*$D6 -> 50843.617 | AJ6: =AH6-AI6 -> 20337.447 | AK6: =$B6/12 -> 25.833333 | AL6: =AK6*$C6 -> 71181.063 | AM6: =AK6*$D6 -> 50843.617 | AN6: =AL6-AM6 -> 20337.447 | AO6: =$B6/12 -> 25.833333 | AP6: =AO6*$C6 -> 71181.063 | AQ6: =AO6*$D6 -> 50843.617 | AR6: =AP6-AQ6 -> 20337.447 | AS6: =$B6/12 -> 25.833333 | AT6: =AS6*$C6 -> 71181.063 | AU6: =AS6*$D6 -> 50843.617 | AV6: =AT6-AU6 -> 20337.447 | AW6: =$B6/12 -> 25.833333 | AX6: =AW6*$C6 -> 71181.063 | AY6: =AW6*$D6 -> 50843.617 | AZ6: =AX6-AY6 -> 20337.447
A7: Launch Ramp | B7: =Assumptions!M14 -> 124 | C7: =Assumptions!S14 -> 497.08867 | D7: =Assumptions!R14 -> 355.06333 | E7: =$B7/12 -> 10.333333 | F7: =E7*$C7 -> 5136.5829 | G7: =E7*$D7 -> 3668.9878 | H7: =F7-G7 -> 1467.5951 | I7: =$B7/12 -> 10.333333 | J7: =I7*$C7 -> 5136.5829 | K7: =I7*$D7 -> 3668.9878 | L7: =J7-K7 -> 1467.5951 | M7: =$B7/12 -> 10.333333 | N7: =M7*$C7 -> 5136.5829 | O7: =M7*$D7 -> 3668.9878 | P7: =N7-O7 -> 1467.5951 | Q7: =$B7/12 -> 10.333333 | R7: =Q7*$C7 -> 5136.5829 | S7: =Q7*$D7 -> 3668.9878 | T7: =R7-S7 -> 1467.5951 | U7: =$B7/12 -> 10.333333 | V7: =U7*$C7 -> 5136.5829 | W7: =U7*$D7 -> 3668.9878 | X7: =V7-W7 -> 1467.5951 | Y7: =$B7/12 -> 10.333333 | Z7: =Y7*$C7 -> 5136.5829 | AA7: =Y7*$D7 -> 3668.9878 | AB7: =Z7-AA7 -> 1467.5951 | AC7: =$B7/12 -> 10.333333 | AD7: =AC7*$C7 -> 5136.5829 | AE7: =AC7*$D7 -> 3668.9878 | AF7: =AD7-AE7 -> 1467.5951 | AG7: =$B7/12 -> 10.333333 | AH7: =AG7*$C7 -> 5136.5829 | AI7: =AG7*$D7 -> 3668.9878 | AJ7: =AH7-AI7 -> 1467.5951 | AK7: =$B7/12 -> 10.333333 | AL7: =AK7*$C7 -> 5136.5829 | AM7: =AK7*$D7 -> 3668.9878 | AN7: =AL7-AM7 -> 1467.5951 | AO7: =$B7/12 -> 10.333333 | AP7: =AO7*$C7 -> 5136.5829 | AQ7: =AO7*$D7 -> 3668.9878 | AR7: =AP7-AQ7 -> 1467.5951 | AS7: =$B7/12 -> 10.333333 | AT7: =AS7*$C7 -> 5136.5829 | AU7: =AS7*$D7 -> 3668.9878 | AV7: =AT7-AU7 -> 1467.5951 | AW7: =$B7/12 -> 10.333333 | AX7: =AW7*$C7 -> 5136.5829 | AY7: =AW7*$D7 -> 3668.9878 | AZ7: =AX7-AY7 -> 1467.5951
A8: Skatelite Upgrade | B8: =Assumptions!M15 -> 186 | C8: =Assumptions!S15 -> 5426.1153 | D8: =Assumptions!R15 -> 3875.7967 | E8: =$B8/12 -> 15.5 | F8: =E8*$C8 -> 84104.788 | G8: =E8*$D8 -> 60074.848 | H8: =F8-G8 -> 24029.939 | I8: =$B8/12 -> 15.5 | J8: =I8*$C8 -> 84104.788 | K8: =I8*$D8 -> 60074.848 | L8: =J8-K8 -> 24029.939 | M8: =$B8/12 -> 15.5 | N8: =M8*$C8 -> 84104.788 | O8: =M8*$D8 -> 60074.848 | P8: =N8-O8 -> 24029.939 | Q8: =$B8/12 -> 15.5 | R8: =Q8*$C8 -> 84104.788 | S8: =Q8*$D8 -> 60074.848 | T8: =R8-S8 -> 24029.939 | U8: =$B8/12 -> 15.5 | V8: =U8*$C8 -> 84104.788 | W8: =U8*$D8 -> 60074.848 | X8: =V8-W8 -> 24029.939 | Y8: =$B8/12 -> 15.5 | Z8: =Y8*$C8 -> 84104.788 | AA8: =Y8*$D8 -> 60074.848 | AB8: =Z8-AA8 -> 24029.939 | AC8: =$B8/12 -> 15.5 | AD8: =AC8*$C8 -> 84104.788 | AE8: =AC8*$D8 -> 60074.848 | AF8: =AD8-AE8 -> 24029.939 | AG8: =$B8/12 -> 15.5 | AH8: =AG8*$C8 -> 84104.788 | AI8: =AG8*$D8 -> 60074.848 | AJ8: =AH8-AI8 -> 24029.939 | AK8: =$B8/12 -> 15.5 | AL8: =AK8*$C8 -> 84104.788 | AM8: =AK8*$D8 -> 60074.848 | AN8: =AL8-AM8 -> 24029.939 | AO8: =$B8/12 -> 15.5 | AP8: =AO8*$C8 -> 84104.788 | AQ8: =AO8*$D8 -> 60074.848 | AR8: =AP8-AQ8 -> 24029.939 | AS8: =$B8/12 -> 15.5 | AT8: =AS8*$C8 -> 84104.788 | AU8: =AS8*$D8 -> 60074.848 | AV8: =AT8-AU8 -> 24029.939 | AW8: =$B8/12 -> 15.5 | AX8: =AW8*$C8 -> 84104.788 | AY8: =AW8*$D8 -> 60074.848 | AZ8: =AX8-AY8 -> 24029.939
A9: Coping Upgrade | B9: =Assumptions!M16 -> 124 | C9: =Assumptions!S16 -> 512.53533 | D9: =Assumptions!R16 -> 366.09667 | E9: =$B9/12 -> 10.333333 | F9: =E9*$C9 -> 5296.1984 | G9: =E9*$D9 -> 3782.9989 | H9: =F9-G9 -> 1513.1996 | I9: =$B9/12 -> 10.333333 | J9: =I9*$C9 -> 5296.1984 | K9: =I9*$D9 -> 3782.9989 | L9: =J9-K9 -> 1513.1996 | M9: =$B9/12 -> 10.333333 | N9: =M9*$C9 -> 5296.1984 | O9: =M9*$D9 -> 3782.9989 | P9: =N9-O9 -> 1513.1996 | Q9: =$B9/12 -> 10.333333 | R9: =Q9*$C9 -> 5296.1984 | S9: =Q9*$D9 -> 3782.9989 | T9: =R9-S9 -> 1513.1996 | U9: =$B9/12 -> 10.333333 | V9: =U9*$C9 -> 5296.1984 | W9: =U9*$D9 -> 3782.9989 | X9: =V9-W9 -> 1513.1996 | Y9: =$B9/12 -> 10.333333 | Z9: =Y9*$C9 -> 5296.1984 | AA9: =Y9*$D9 -> 3782.9989 | AB9: =Z9-AA9 -> 1513.1996 | AC9: =$B9/12 -> 10.333333 | AD9: =AC9*$C9 -> 5296.1984 | AE9: =AC9*$D9 -> 3782.9989 | AF9: =AD9-AE9 -> 1513.1996 | AG9: =$B9/12 -> 10.333333 | AH9: =AG9*$C9 -> 5296.1984 | AI9: =AG9*$D9 -> 3782.9989 | AJ9: =AH9-AI9 -> 1513.1996 | AK9: =$B9/12 -> 10.333333 | AL9: =AK9*$C9 -> 5296.1984 | AM9: =AK9*$D9 -> 3782.9989 | AN9: =AL9-AM9 -> 1513.1996 | AO9: =$B9/12 -> 10.333333 | AP9: =AO9*$C9 -> 5296.1984 | AQ9: =AO9*$D9 -> 3782.9989 | AR9: =AP9-AQ9 -> 1513.1996 | AS9: =$B9/12 -> 10.333333 | AT9: =AS9*$C9 -> 5296.1984 | AU9: =AS9*$D9 -> 3782.9989 | AV9: =AT9-AU9 -> 1513.1996 | AW9: =$B9/12 -> 10.333333 | AX9: =AW9*$C9 -> 5296.1984 | AY9: =AW9*$D9 -> 3782.9989 | AZ9: =AX9-AY9 -> 1513.1996
A10: TOTAL | E10: =SUM(E4:E9) -> 103.33333 | F10: =SUM(F4:F9) -> 191510 | G10: =SUM(G4:G9) -> 136792.86 | H10: =SUM(H4:H9) -> 54717.142 | I10: =SUM(I4:I9) -> 103.33333 | J10: =SUM(J4:J9) -> 191510 | K10: =SUM(K4:K9) -> 136792.86 | L10: =SUM(L4:L9) -> 54717.142 | ... AZ10: =SUM(AZ4:AZ9) -> 54717.142

Sheet Shipping Model
A1: Ramp Dimension Weights
A2: Ramp | B2: Assembled Dimensions | C2: Estimated Crate Dimensions | D2: Est. Weight (lb) | E2: Notes
A3: Quarter Pipe | B3: 4' tall, 8' wide, 8' deep | C3: 96" x 48" x 20" | D3: 425 | E3: Weights estimated from BOM level using plywood, 2x4s, fasteners; Funbox assumed multi-pallet shipment.
A4: Bank Ramp | B4: 3.5' tall, 6' wide, 6' long | C4: 72" x 48" x 18" | D4: 337 | E4: Weights estimated from BOM level using plywood, 2x4s, fasteners; Funbox assumed multi-pallet shipment.
A5: Funbox | B5: 22' x 15.5' footprint | C5: Two pallets 96" x 48" x 30" | D5: 2475 | E5: Weights estimated from BOM level using plywood, 2x4s, fasteners; Funbox assumed multi-pallet shipment.
A6: Launch Ramp | B6: 2' tall, 4' wide, 6' long | C6: 72" x 48" x 16" | D6: 250 | E6: Weights estimated from BOM level using plywood, 2x4s, fasteners; Funbox assumed multi-pallet shipment.
A8: Shipping Zones
A9: Zone | B9: Distance (mi) | C9: Freight Cost per Crate ($) | D9: Market Share
A10: West (Rockies West) | B10: 300–1,200 | C10: 55 | D10: 0.4
A11: South | B11: 1,200–1,800 | C11: 100 | D11: 0.25
A12: Midwest | B12: 1,400–2,100 | C12: 115 | D12: 0.2
A13: Northeast | B13: 2,200–2,700 | C13: 140 | D13: 0.15
A15: Freight allocation
A16: Zone | B16: Freight Cost ($) | C16: Market Share | D16: Weighted Cost ($)
A17: West (Rockies West) | B17: 55 | C17: 0.4 | D17: =B17*C17 -> 22
A18: South | B18: 100 | C18: 0.25 | D18: =B18*C18 -> 25
A19: Midwest | B19: 115 | C19: 0.2 | D19: =B19*C19 -> 23
A20: Northeast | B20: 140 | C20: 0.15 | D20: =B20*C20 -> 21
A21: Average Shipping | D21: =SUM(D17:D20) -> 91
A24: Labels | B24: Reference
A25: Freight Regions | B25: https://www.fedex.com/en-us/shipping/freight.html
A26: Distance | B26: https://www.ups.com/us/en/support/shipping-support/shipping-costs-rates
A27: Freight cost per crate | B27: https://www.tforcefreight.com/
A28: Market share | B28: https://sfia.org/research/
B29: https://www.census.gov/
A30: Weighted Freight Calculation | B30: https://www.freightwaves.com/
A31: Ramp Dimension | B31: https://freshpark.com/
A32: Freight Class guidance | B32: https://www.odfl.com/

Sheet CVP
A1: CVP Analysis (Scenario Driven)
A3: Scenario | B3: =Assumptions!B3 -> Base Case
A4: Annual Fixed Costs | B4: =Assumptions!E4 -> 225192.54
A6: Total annual units | B6: =SUM(Assumptions!C11:C16) -> 1240
A7: Annual Revenue | B7: ='Monthly FP&A'!F10+'Monthly FP&A'!J10+'Monthly FP&A'!N10+'Monthly FP&A'!R10+'Monthly FP&A'!V10+'Monthly FP&A'!Z10+'Monthly FP&A'!AD10+'Monthly FP&A'!AH10+'Monthly FP&A'!AL10+'Monthly FP&A'!AP10+'Monthly FP&A'!AT10+'Monthly FP&A'!AX10 -> 2298120
A8: Annual Variable Cost | B8: ='Monthly FP&A'!G10+'Monthly FP&A'!K10+'Monthly FP&A'!O10+'Monthly FP&A'!S10+'Monthly FP&A'!W10+'Monthly FP&A'!AA10+'Monthly FP&A'!AE10+'Monthly FP&A'!AI10+'Monthly FP&A'!AM10+'Monthly FP&A'!AQ10+'Monthly FP&A'!AU10+'Monthly FP&A'!AY10 -> 1641514.3
A9: Annual Contribution Margin | B9: ='Monthly FP&A'!H10+'Monthly FP&A'!L10+'Monthly FP&A'!P10+'Monthly FP&A'!T10+'Monthly FP&A'!X10+'Monthly FP&A'!AB10+'Monthly FP&A'!AF10+'Monthly FP&A'!AJ10+'Monthly FP&A'!AN10+'Monthly FP&A'!AR10+'Monthly FP&A'!AV10+'Monthly FP&A'!AZ10 -> 656605.71
A10: CM % | B10: =IF(B7=0,0,B9/B7) -> 0.28571429
A11: Break-even Revenue | B11: =IF(B10=0,0,B4/B10) -> 788173.9
A12: Break-even Units (Weighted Avg) | B12: =IF(B9=0,0,B11/SUM(B19)) -> 425.27616
A14: Variable Cost | B14: =B8 -> 1641514.3
A15: Total O.H Cost | B15: =SUM('ABC Allocation'!I14:I19) -> 256230.48
A16: Total Cost | B16: =SUM(B14:B15) -> 1897744.8
A19: Weighted Avg Price | B19: =B7/B6 -> 1853.3226
D20: Units | E20: Revenues | F20: Cost | G20: Profit
D21: 0 | E21: =D21*$B$19 -> 0 | F21: =((1-$B$10)*E21)+$B$4 -> 225192.54 | G21: =(E21*$B$10)-$B$4 -> -225192.54
D22: 100 | E22: =D22*$B$19 -> 185332.26 | F22: =((1-$B$10)*E22)+$B$4 -> 357572.73 | G22: =(E22*$B$10)-$B$4 -> -172240.47
D23: 200 | E23: =D23*$B$19 -> 370664.51 | F23: =((1-$B$10)*E23)+$B$4 -> 489952.91 | G23: =(E23*$B$10)-$B$4 -> -119288.4
D24: 300 | E24: =D24*$B$19 -> 555996.77 | F24: =((1-$B$10)*E24)+$B$4 -> 622333.09 | G24: =(E24*$B$10)-$B$4 -> -66336.323
D25: 400 | E25: =D25*$B$19 -> 741329.03 | F25: =((1-$B$10)*E25)+$B$4 -> 754713.28 | G25: =(E25*$B$10)-$B$4 -> -13384.25
D26: 500 | E26: =D26*$B$19 -> 926661.28 | F26: =((1-$B$10)*E26)+$B$4 -> 887093.46 | G26: =(E26*$B$10)-$B$4 -> 39567.824
D27: 600 | E27: =D27*$B$19 -> 1111993.5 | F27: =((1-$B$10)*E27)+$B$4 -> 1019473.6 | G27: =(E27*$B$10)-$B$4 -> 92519.897
D28: 700 | E28: =D28*$B$19 -> 1297325.8 | F28: =((1-$B$10)*E28)+$B$4 -> 1151853.8 | G28: =(E28*$B$10)-$B$4 -> 145471.97
D29: 800 | E29: =D29*$B$19 -> 1482658.1 | F29: =((1-$B$10)*E29)+$B$4 -> 1284234 | G29: =(E29*$B$10)-$B$4 -> 198424.04
D30: 900 | E30: =D30*$B$19 -> 1667990.3 | F30: =((1-$B$10)*E30)+$B$4 -> 1416614.2 | G30: =(E30*$B$10)-$B$4 -> 251376.12
D31: 1000 | E31: =D31*$B$19 -> 1853322.6 | F31: =((1-$B$10)*E31)+$B$4 -> 1548994.4 | G31: =(E31*$B$10)-$B$4 -> 304328.19
B42: Products | C42: Units | D42: Price/unit | E42: Variable Cost/unit | F42: C.M/unit | G42: Total C.M
B43: =Assumptions!A11 -> Quarter Pipe | C43: =Assumptions!M11 -> 248 | D43: =Assumptions!S11 -> 669.46133 | E43: =Assumptions!R11 -> 478.18667 | F43: =D43-E43 -> 191.27467 | G43: =F43*C43 -> 47436.117
B44: =Assumptions!A12 -> Bank Ramp | C44: =Assumptions!M12 -> 248 | D44: =Assumptions!S12 -> 578.508 | E44: =Assumptions!R12 -> 413.22 | F44: =D44-E44 -> 165.288 | G44: =F44*C44 -> 40991.424
B45: =Assumptions!A13 -> Funbox | C45: =Assumptions!M13 -> 310 | D45: =Assumptions!S13 -> 2755.396 | E45: =Assumptions!R13 -> 1968.14 | F45: =D45-E45 -> 787.256 | G45: =F45*C45 -> 244049.36
B46: =Assumptions!A14 -> Launch Ramp | C46: =Assumptions!M14 -> 124 | D46: =Assumptions!S14 -> 497.08867 | E46: =Assumptions!R14 -> 355.06333 | F46: =D46-E46 -> 142.02533 | G46: =F46*C46 -> 17611.141
B47: =Assumptions!A15 -> Skatelite Upgrade | C47: =Assumptions!M15 -> 186 | D47: =Assumptions!S15 -> 5426.1153 | E47: =Assumptions!R15 -> 3875.7967 | F47: =D47-E47 -> 1550.3187 | G47: =F47*C47 -> 288359.27
B48: =Assumptions!A16 -> Coping Upgrade | C48: =Assumptions!M16 -> 124 | D48: =Assumptions!S16 -> 512.53533 | E48: =Assumptions!R16 -> 366.09667 | F48: =D48-E48 -> 146.43867 | G48: =F48*C48 -> 18158.395

Sheet Traceability
A1: Traceability Notes
A3: BOM materials per unit are pulled from BOM Sheet (2).xlsx totals (Qty × Unit Cost) for each ramp.
A4: Shipping cost per unit is an input from Member 3 (logistics model) and is embedded in variable cost.
A5: Scenario selector drives multipliers for units, materials, labor, shipping, and other variable costs.
A6: Monthly FP&A rolls annual units into equal monthly units (Annual/12). Adjust monthly seasonality if needed.
